Workbook

Sheet How to use
B1: Aptimizer Phase II: test tracking sheet
B2: One tab per stage. Each tab lists every test, grouped by person (A, B, C).
B4: What you do (testers)
B5: 1. Open the tab for the stage we're on and find your letter (coloured band).
B6: 2. Run the test in the app. Type the app's answer in the yellow App answer column.
B7: 3. Type the correct answer from the book, the code or RERA in Correct answer. Some are already filled in.
B8: 4. Write where you got it: book name + page, or RERA registration number.
B9: 5. The Result column turns green (Pass) or red (Fail) by itself. Write anything odd in Notes.
B10: 6. Every Friday, upload the file to the shared folder. That's it.
B12: Typing rules
B13: • Numbers only in answer cells: type 1404, not 1404 kN. The unit is in the Unit column.
B14: • Percentages as plain numbers: type 35 for 35%.
... B33: What to test: IITGN EQ3 Example 1: base shear Vb | App answer: 1398.6 | Correct answer: 1404 | Where you got it: IITGN-WB-EQ3, Example 1, page 12 | Off by: -0.4% | Result: Pass

Sheet Summary
A1: Progress and pass rates (fills itself)
A2: Book = solved example from a textbook or code (target 100%). Real = real RERA data or a hand calculation (target 90%). Pass rate = passed ÷ (passed + failed).
A4: Stage | B4: Total tests | C4: Passed | D4: Failed | E4: Skipped (not tested) | F4: Still to do | G4: Book examples passed | H4: Book target 100% met? | I4: Real-data checks passed | J4: Real target 90% met? | K4: Before fixes: book passed | L4: Before fixes: real passed
A5: Stage 1 | B5: =COUNTIF('Stage 1'!$A$6:$A$165,"?*") | C5: =COUNTIF('Stage 1'!$M$6:$M$165,"Pass") | D5: =COUNTIF('Stage 1'!$M$6:$M$165,"Fail") | E5: =COUNTIF('Stage 1'!$M$6:$M$165,"Not tested") | F5: =COUNTIF('Stage 1'!$M$6:$M$165,"Not done yet")+COUNTIF('Stage 1'!$M$6:$M$165,"Claude will check") | G5: =IF((COUNTIFS('Stage 1'!$F$6:$F$165,"Book",'Stage 1'!$M$6:$M$165,"Pass")+COUNTIFS('Stage 1'!$F$6:$F$165,"Book",'Stage 1'!$M$6:$M$165,"Fail"))=0,"",COUNTIFS('Stage 1'!$F$6:$F$165,"Book",'Stage 1'!$M$6:$M$165,"Pass")/(COUNTIFS('Stage 1'!$F$6:$F$165,"Book",'Stage 1'!$M$6:$M$165,"Pass")+COUNTIFS('Stage 1'!$F$6:$F$165,"Book",'Stage 1'!$M$6:$M$165,"Fail"))) | H5: =IF(G5="","",IF(G5>=1,"Yes","Not yet")) | I5: =IF((COUNTIFS('Stage 1'!$F$6:$F$165,"Real",'Stage 1'!$M$6:$M$165,"Pass")+COUNTIFS('Stage 1'!$F$6:$F$165,"Real",'Stage 1'!$M$6:$M$165,"Fail"))=0,"",COUNTIFS('Stage 1'!$F$6:$F$165,"Real",'Stage 1'!$M$6:$M$165,"Pass")/(COUNTIFS('Stage 1'!$F$6:$F$165,"Real",'Stage 1'!$M$6:$M$165,"Pass")+COUNTIFS('Stage 1'!$F$6:$F$165,"Real",'Stage 1'!$M$6:$M$165,"Fail"))) | J5: =IF(I5="","",IF(I5>=0.9,"Yes","Not yet")) | K5: =IF((COUNTIFS('Stage 1'!$F$6:$F$165,"Book",'Stage 1'!$P$6:$P$165,"Pass")+COUNTIFS('Stage 1'!$F$6:$F$165,"Book",'Stage 1'!$P$6:$P$165,"Fail"))=0,"",COUNTIFS('Stage 1'!$F$6:$F$165,"Book",'Stage 1'!$P$6:$P$165,"Pass")/(COUNTIFS('Stage 1'!$F$6:$F$165,"Book",'Stage 1'!$P$6:$P$165,"Pass")+COUNTIFS('Stage 1'!$F$6:$F$165,"Book",'Stage 1'!$P$6:$P$165,"Fail"))) | L5: =IF((COUNTIFS('Stage 1'!$F$6:$F$165,"Real",'Stage 1'!$P$6:$P$165,"Pass")+COUNTIFS('Stage 1'!$F$6:$F$165,"Real",'Stage 1'!$P$6:$P$165,"Fail"))=0,"",COUNTIFS('Stage 1'!$F$6:$F$165,"Real",'Stage 1'!$P$6:$P$165,"Pass")/(COUNTIFS('Stage 1'!$F$6:$F$165,"Real",'Stage 1'!$P$6:$P$165,"Pass")+COUNTIFS('Stage 1'!$F$6:$F$165,"Real",'Stage 1'!$P$6:$P$165,"Fail")))
A6: Stage 2 | B6: =COUNTIF('Stage 2'!$A$6:$A$195,"?*") | C6: =COUNTIF('Stage 2'!$M$6:$M$195,"Pass") | D6: =COUNTIF('Stage 2'!$M$6:$M$195,"Fail") | E6: =COUNTIF('Stage 2'!$M$6:$M$195,"Not tested") | F6: =COUNTIF('Stage 2'!$M$6:$M$195,"Not done yet")+COUNTIF('Stage 2'!$M$6:$M$195,"Claude will check") | G6: =IF((COUNTIFS('Stage 2'!$F$6:$F$195,"Book",'Stage 2'!$M$6:$M$195,"Pass")+COUNTIFS('Stage 2'!$F$6:$F$195,"Book",'Stage 2'!$M$6:$M$195,"Fail"))=0,"",COUNTIFS('Stage 2'!$F$6:$F$195,"Book",'Stage 2'!$M$6:$M$195,"Pass")/(COUNTIFS('Stage 2'!$F$6:$F$195,"Book",'Stage 2'!$M$6:$M$195,"Pass")+COUNTIFS('Stage 2'!$F$6:$F$195,"Book",'Stage 2'!$M$6:$M$195,"Fail"))) | H6: =IF(G6="","",IF(G6>=1,"Yes","Not yet")) | I6: =IF((COUNTIFS('Stage 2'!$F$6:$F$195,"Real",'Stage 2'!$M$6:$M$195,"Pass")+COUNTIFS('Stage 2'!$F$6:$F$195,"Real",'Stage 2'!$M$6:$M$195,"Fail"))=0,"",COUNTIFS('Stage 2'!$F$6:$F$195,"Real",'Stage 2'!$M$6:$M$195,"Pass")/(COUNTIFS('Stage 2'!$F$6:$F$195,"Real",'Stage 2'!$M$6:$M$195,"Pass")+COUNTIFS('Stage 2'!$F$6:$F$195,"Real",'Stage 2'!$M$6:$M$195,"Fail"))) | J6: =IF(I6="","",IF(I6>=0.9,"Yes","Not yet")) | K6: =IF((COUNTIFS('Stage 2'!$F$6:$F$195,"Book",'Stage 2'!$P$6:$P$195,"Pass")+COUNTIFS('Stage 2'!$F$6:$F$195,"Book",'Stage 2'!$P$6:$P$195,"Fail"))=0,"",COUNTIFS('Stage 2'!$F$6:$F$195,"Book",'Stage 2'!$P$6:$P$195,"Pass")/(COUNTIFS('Stage 2'!$F$6:$F$195,"Book",'Stage 2'!$P$6:$P$195,"Pass")+COUNTIFS('Stage 2'!$F$6:$F$195,"Book",'Stage 2'!$P$6:$P$195,"Fail"))) | L6: =IF((COUNTIFS('Stage 2'!$F$6:$F$195,"Real",'Stage 2'!$P$6:$P$195,"Pass")+COUNTIFS('Stage 2'!$F$6:$F$195,"Real",'Stage 2'!$P$6:$P$195,"Fail"))=0,"",COUNTIFS('Stage 2'!$F$6:$F$195,"Real",'Stage 2'!$P$6:$P$195,"Pass")/(COUNTIFS('Stage 2'!$F$6:$F$195,"Real",'Stage 2'!$P$6:$P$195,"Pass")+COUNTIFS('Stage 2'!$F$6:$F$195,"Real",'Stage 2'!$P$6:$P$195,"Fail")))
A7: Stage 3 | B7: =COUNTIF('Stage 3'!$A$6:$A$189,"?*") | C7: =COUNTIF('Stage 3'!$M$6:$M$189,"Pass") | D7: =COUNTIF('Stage 3'!$M$6:$M$189,"Fail") | E7: =COUNTIF('Stage 3'!$M$6:$M$189,"Not tested") | F7: =COUNTIF('Stage 3'!$M$6:$M$189,"Not done yet")+COUNTIF('Stage 3'!$M$6:$M$189,"Claude will check") | G7: =IF((COUNTIFS('Stage 3'!$F$6:$F$189,"Book",'Stage 3'!$M$6:$M$189,"Pass")+COUNTIFS('Stage 3'!$F$6:$F$189,"Book",'Stage 3'!$M$6:$M$189,"Fail"))=0,"",COUNTIFS('Stage 3'!$F$6:$F$189,"Book",'Stage 3'!$M$6:$M$189,"Pass")/(COUNTIFS('Stage 3'!$F$6:$F$189,"Book",'Stage 3'!$M$6:$M$189,"Pass")+COUNTIFS('Stage 3'!$F$6:$F$189,"Book",'Stage 3'!$M$6:$M$189,"Fail"))) | H7: =IF(G7="","",IF(G7>=1,"Yes","Not yet")) | I7: =IF((COUNTIFS('Stage 3'!$F$6:$F$189,"Real",'Stage 3'!$M$6:$M$189,"Pass")+COUNTIFS('Stage 3'!$F$6:$F$189,"Real",'Stage 3'!$M$6:$M$189,"Fail"))=0,"",COUNTIFS('Stage 3'!$F$6:$F$189,"Real",'Stage 3'!$M$6:$M$189,"Pass")/(COUNTIFS('Stage 3'!$F$6:$F$189,"Real",'Stage 3'!$M$6:$M$189,"Pass")+COUNTIFS('Stage 3'!$F$6:$F$189,"Real",'Stage 3'!$M$6:$M$189,"Fail"))) | J7: =IF(I7="","",IF(I7>=0.9,"Yes","Not yet")) | K7: =IF((COUNTIFS('Stage 3'!$F$6:$F$189,"Book",'Stage 3'!$P$6:$P$189,"Pass")+COUNTIFS('Stage 3'!$F$6:$F$189,"Book",'Stage 3'!$P$6:$P$189,"Fail"))=0,"",COUNTIFS('Stage 3'!$F$6:$F$189,"Book",'Stage 3'!$P$6:$P$189,"Pass")/(COUNTIFS('Stage 3'!$F$6:$F$189,"Book",'Stage 3'!$P$6:$P$189,"Pass")+COUNTIFS('Stage 3'!$F$6:$F$189,"Book",'Stage 3'!$P$6:$P$189,"Fail"))) | L7: =IF((COUNTIFS('Stage 3'!$F$6:$F$189,"Real",'Stage 3'!$P$6:$P$189,"Pass")+COUNTIFS('Stage 3'!$F$6:$F$189,"Real",'Stage 3'!$P$6:$P$189,"Fail"))=0,"",COUNTIFS('Stage 3'!$F$6:$F$189,"Real",'Stage 3'!$P$6:$P$189,"Pass")/(COUNTIFS('Stage 3'!$F$6:$F$189,"Real",'Stage 3'!$P$6:$P$189,"Pass")+COUNTIFS('Stage 3'!$F$6:$F$189,"Real",'Stage 3'!$P$6:$P$189,"Fail")))
A8: Stage 4 | B8: =COUNTIF('Stage 4'!$A$6:$A$185,"?*") | C8: =COUNTIF('Stage 4'!$M$6:$M$185,"Pass") | D8: =COUNTIF('Stage 4'!$M$6:$M$185,"Fail") | E8: =COUNTIF('Stage 4'!$M$6:$M$185,"Not tested") | F8: =COUNTIF('Stage 4'!$M$6:$M$185,"Not done yet")+COUNTIF('Stage 4'!$M$6:$M$185,"Claude will check") | G8: =IF((COUNTIFS('Stage 4'!$F$6:$F$185,"Book",'Stage 4'!$M$6:$M$185,"Pass")+COUNTIFS('Stage 4'!$F$6:$F$185,"Book",'Stage 4'!$M$6:$M$185,"Fail"))=0,"",COUNTIFS('Stage 4'!$F$6:$F$185,"Book",'Stage 4'!$M$6:$M$185,"Pass")/(COUNTIFS('Stage 4'!$F$6:$F$185,"Book",'Stage 4'!$M$6:$M$185,"Pass")+COUNTIFS('Stage 4'!$F$6:$F$185,"Book",'Stage 4'!$M$6:$M$185,"Fail"))) | H8: =IF(G8="","",IF(G8>=1,"Yes","Not yet")) | I8: =IF((COUNTIFS('Stage 4'!$F$6:$F$185,"Real",'Stage 4'!$M$6:$M$185,"Pass")+COUNTIFS('Stage 4'!$F$6:$F$185,"Real",'Stage 4'!$M$6:$M$185,"Fail"))=0,"",COUNTIFS('Stage 4'!$F$6:$F$185,"Real",'Stage 4'!$M$6:$M$185,"Pass")/(COUNTIFS('Stage 4'!$F$6:$F$185,"Real",'Stage 4'!$M$6:$M$185,"Pass")+COUNTIFS('Stage 4'!$F$6:$F$185,"Real",'Stage 4'!$M$6:$M$185,"Fail"))) | J8: =IF(I8="","",IF(I8>=0.9,"Yes","Not yet")) | K8: =IF((COUNTIFS('Stage 4'!$F$6:$F$185,"Book",'Stage 4'!$P$6:$P$185,"Pass")+COUNTIFS('Stage 4'!$F$6:$F$185,"Book",'Stage 4'!$P$6:$P$185,"Fail"))=0,"",COUNTIFS('Stage 4'!$F$6:$F$185,"Book",'Stage 4'!$P$6:$P$185,"Pass")/(COUNTIFS('Stage 4'!$F$6:$F$185,"Book",'Stage 4'!$P$6:$P$185,"Pass")+COUNTIFS('Stage 4'!$F$6:$F$185,"Book",'Stage 4'!$P$6:$P$185,"Fail"))) | L8: =IF((COUNTIFS('Stage 4'!$F$6:$F$185,"Real",'Stage 4'!$P$6:$P$185,"Pass")+COUNTIFS('Stage 4'!$F$6:$F$185,"Real",'Stage 4'!$P$6:$P$185,"Fail"))=0,"",COUNTIFS('Stage 4'!$F$6:$F$185,"Real",'Stage 4'!$P$6:$P$185,"Pass")/(COUNTIFS('Stage 4'!$F$6:$F$185,"Real",'Stage 4'!$P$6:$P$185,"Pass")+COUNTIFS('Stage 4'!$F$6:$F$185,"Real",'Stage 4'!$P$6:$P$185,"Fail")))
A9: Stage 5 | B9: =COUNTIF('Stage 5'!$A$6:$A$131,"?*") | C9: =COUNTIF('Stage 5'!$M$6:$M$131,"Pass") | D9: =COUNTIF('Stage 5'!$M$6:$M$131,"Fail") | E9: =COUNTIF('Stage 5'!$M$6:$M$131,"Not tested") | F9: =COUNTIF('Stage 5'!$M$6:$M$131,"Not done yet")+COUNTIF('Stage 5'!$M$6:$M$131,"Claude will check") | G9: =IF((COUNTIFS('Stage 5'!$F$6:$F$131,"Book",'Stage 5'!$M$6:$M$131,"Pass")+COUNTIFS('Stage 5'!$F$6:$F$131,"Book",'Stage 5'!$M$6:$M$131,"Fail"))=0,"",COUNTIFS('Stage 5'!$F$6:$F$131,"Book",'Stage 5'!$M$6:$M$131,"Pass")/(COUNTIFS('Stage 5'!$F$6:$F$131,"Book",'Stage 5'!$M$6:$M$131,"Pass")+COUNTIFS('Stage 5'!$F$6:$F$131,"Book",'Stage 5'!$M$6:$M$131,"Fail"))) | H9: =IF(G9="","",IF(G9>=1,"Yes","Not yet")) | I9: =IF((COUNTIFS('Stage 5'!$F$6:$F$131,"Real",'Stage 5'!$M$6:$M$131,"Pass")+COUNTIFS('Stage 5'!$F$6:$F$131,"Real",'Stage 5'!$M$6:$M$131,"Fail"))=0,"",COUNTIFS('Stage 5'!$F$6:$F$131,"Real",'Stage 5'!$M$6:$M$131,"Pass")/(COUNTIFS('Stage 5'!$F$6:$F$131,"Real",'Stage 5'!$M$6:$M$131,"Pass")+COUNTIFS('Stage 5'!$F$6:$F$131,"Real",'Stage 5'!$M$6:$M$131,"Fail"))) | J9: =IF(I9="","",IF(I9>=0.9,"Yes","Not yet")) | K9: =IF((COUNTIFS('Stage 5'!$F$6:$F$131,"Book",'Stage 5'!$P$6:$P$131,"Pass")+COUNTIFS('Stage 5'!$F$6:$F$131,"Book",'Stage 5'!$P$6:$P$131,"Fail"))=0,"",COUNTIFS('Stage 5'!$F$6:$F$131,"Book",'Stage 5'!$P$6:$P$131,"Pass")/(COUNTIFS('Stage 5'!$F$6:$F$131,"Book",'Stage 5'!$P$6:$P$131,"Pass")+COUNTIFS('Stage 5'!$F$6:$F$131,"Book",'Stage 5'!$P$6:$P$131,"Fail"))) | L9: =IF((COUNTIFS('Stage 5'!$F$6:$F$131,"Real",'Stage 5'!$P$6:$P$131,"Pass")+COUNTIFS('Stage 5'!$F$6:$F$131,"Real",'Stage 5'!$P$6:$P$131,"Fail"))=0,"",COUNTIFS('Stage 5'!$F$6:$F$131,"Real",'Stage 5'!$P$6:$P$131,"Pass")/(COUNTIFS('Stage 5'!$F$6:$F$131,"Real",'Stage 5'!$P$6:$P$131,"Pass")+COUNTIFS('Stage 5'!$F$6:$F$131,"Real",'Stage 5'!$P$6:$P$131,"Fail")))
A10: Replay | B10: =COUNTIF(Replay!$A$6:$A$120,"?*") | C10: =COUNTIF(Replay!$M$6:$M$120,"Pass") | D10: =COUNTIF(Replay!$M$6:$M$120,"Fail") | E10: =COUNTIF(Replay!$M$6:$M$120,"Not tested") | F10: =COUNTIF(Replay!$M$6:$M$120,"Not done yet")+COUNTIF(Replay!$M$6:$M$120,"Claude will check") | G10: =IF((COUNTIFS(Replay!$F$6:$F$120,"Book",Replay!$M$6:$M$120,"Pass")+COUNTIFS(Replay!$F$6:$F$120,"Book",Replay!$M$6:$M$120,"Fail"))=0,"",COUNTIFS(Replay!$F$6:$F$120,"Book",Replay!$M$6:$M$120,"Pass")/(COUNTIFS(Replay!$F$6:$F$120,"Book",Replay!$M$6:$M$120,"Pass")+COUNTIFS(Replay!$F$6:$F$120,"Book",Replay!$M$6:$M$120,"Fail"))) | H10: =IF(G10="","",IF(G10>=1,"Yes","Not yet")) | I10: =IF((COUNTIFS(Replay!$F$6:$F$120,"Real",Replay!$M$6:$M$120,"Pass")+COUNTIFS(Replay!$F$6:$F$120,"Real",Replay!$M$6:$M$120,"Fail"))=0,"",COUNTIFS(Replay!$F$6:$F$120,"Real",Replay!$M$6:$M$120,"Pass")/(COUNTIFS(Replay!$F$6:$F$120,"Real",Replay!$M$6:$M$120,"Pass")+COUNTIFS(Replay!$F$6:$F$120,"Real",Replay!$M$6:$M$120,"Fail"))) | J10: =IF(I10="","",IF(I10>=0.9,"Yes","Not yet")) | K10: =IF((COUNTIFS(Replay!$F$6:$F$120,"Book",Replay!$P$6:$P$120,"Pass")+COUNTIFS(Replay!$F$6:$F$120,"Book",Replay!$P$6:$P$120,"Fail"))=0,"",COUNTIFS(Replay!$F$6:$F$120,"Book",Replay!$P$6:$P$120,"Pass")/(COUNTIFS(Replay!$F$6:$F$120,"Book",Replay!$P$6:$P$120,"Pass")+COUNTIFS(Replay!$F$6:$F$120,"Book",Replay!$P$6:$P$120,"Fail"))) | L10: =IF((COUNTIFS(Replay!$F$6:$F$120,"Real",Replay!$P$6:$P$120,"Pass")+COUNTIFS(Replay!$F$6:$F$120,"Real",Replay!$P$6:$P$120,"Fail"))=0,"",COUNTIFS(Replay!$F$6:$F$120,"Real",Replay!$P$6:$P$120,"Pass")/(COUNTIFS(Replay!$F$6:$F$120,"Real",Replay!$P$6:$P$120,"Pass")+COUNTIFS(Replay!$F$6:$F$120,"Real",Replay!$P$6:$P$120,"Fail")))
A11: All | B11: =SUM(B5:B10) | C11: =SUM(C5:C10) | D11: =SUM(D5:D10) | E11: =SUM(E5:E10) | F11: =SUM(F5:F10)

Sheet Stage 1
A1: Stage 1 Site analysis enhancement (week 2)
A2: HOW TO FILL: 1) Find your letter. 2) Run the test in the app and type its answer in App answer. 3) Type the correct answer from the book or RERA in Correct answer (some are already filled). 4) Write where you got it. 5) Result fills itself. Don't change grey cells.
A4: Yellow = you fill · Grey = fixed plan, don't change · Blue = Claude fills · Click + above column R to see technical details
A5: # | B5: Who | C5: Topic | D5: What to test | E5: Unit | F5: Type | G5: Compare with | H5: Pass if | I5: App answer | J5: Correct answer | K5: Where you got it (book + page, or RERA no.) | L5: Off by | M5: Result | N5: Notes | O5: Claude: override | P5: Claude: first-run result | Q5: Claude: why it failed | R5: Code / clause | S5: Edition | T5: Tol type | U5: Tol low | V5: Tol high | W5: Difference | X5: Error % | Y5: Auto result
B6: A's tests (21)
A7: S1-001 | B7: A | C7: Map source | D7: Plot 1: app reading matches saved Google reply | E7: Yes/No | F7: Book | G7: Saved Google API reply file | H7: Same as correct answer | J7: Yes | L7: =IF(W7="","",W7) | M7: =IF(O7<>"",O7,Y7) | R7: — | S7: n/a | T7: Exact | W7: =IF(AND(ISNUMBER(I7),ISNUMBER(J7)),I7-J7,"") | X7: =IF(AND(ISNUMBER(I7),ISNUMBER(J7)),IF(J7=0,"",(I7-J7)/ABS(J7)),"") | Y7: =IF(T7="Advisory","No pass mark",IF(T7="Manual","Claude will check",IF(I7="","Not done yet",IF(T7="Exact",IF(AND(ISNUMBER(I7),ISNUMBER(J7)),IF(ROUND(I7,2)=ROUND(J7,2),"Pass","Fail"),IF(TRIM(LOWER(I7&""))=TRIM(LOWER(J7&"")),"Pass","Fail")),IF(T7="Min",IF(I7>=U7-1E-9,"Pass","Fail"),IF(T7="Between",IF(AND(I7>=U7,I7<=V7),"Pass","Fail"),IF(J7="","Not done yet",IF(T7="±%",IF(X7="","Check correct answer",IF(ABS(X7)*100<=V7+1E-9,"Pass","Fail")),IF(T7="% range",IF(X7="","Check correct answer",IF(AND(X7*100>=U7-1E-9,X7*100<=V7+1E-9),"Pass","Fail")),IF(T7="±abs",IF(ABS(W7)<=V7+1E-9,"Pass","Fail"),"Check type"))))))))))
A8: S1-002 | B8: A | C8: Map source | D8: Plot 2: app reading matches saved Google reply | E8: Yes/No | F8: Book | G8: Saved Google API reply file | H8: Same as correct answer | J8: Yes | L8: =IF(W8="","",W8) | M8: =IF(O8<>"",O8,Y8) | R8: — | S8: n/a | T8: Exact | W8: =IF(AND(ISNUMBER(I8),ISNUMBER(J8)),I8-J8,"") | X8: =IF(AND(ISNUMBER(I8),ISNUMBER(J8)),IF(J8=0,"",(I8-J8)/ABS(J8)),"") | Y8: =IF(T8="Advisory","No pass mark",IF(T8="Manual","Claude will check",IF(I8="","Not done yet",IF(T8="Exact",IF(AND(ISNUMBER(I8),ISNUMBER(J8)),IF(ROUND(I8,2)=ROUND(J8,2),"Pass","Fail"),IF(TRIM(LOWER(I8&""))=TRIM(LOWER(J8&"")),"Pass","Fail")),IF(T8="Min",IF(I8>=U8-1E-9,"Pass","Fail"),IF(T8="Between",IF(AND(I8>=U8,I8<=V8),"Pass","Fail"),IF(J8="","Not done yet",IF(T8="±%",IF(X8="","Check correct answer",IF(ABS(X8)*100<=V8+1E-9,"Pass","Fail")),IF(T8="% range",IF(X8="","Check correct answer",IF(AND(X8*100>=U8-1E-9,X8*100<=V8+1E-9),"Pass","Fail")),IF(T8="±abs",IF(ABS(W8)<=V8+1E-9,"Pass","Fail"),"Check type"))))))))))
A9: S1-003 | B9: A | C9: Map source | D9: Plot 3: app reading matches saved Google reply | E9: Yes/No | F9: Book | G9: Saved Google API reply file | H9: Same as correct answer | J9: Yes | L9: =IF(W9="","",W9) | M9: =IF(O9<>"",O9,Y9) | R9: — | S9: n/a | T9: Exact | W9: =IF(AND(ISNUMBER(I9),ISNUMBER(J9)),I9-J9,"") | X9: =IF(AND(ISNUMBER(I9),ISNUMBER(J9)),IF(J9=0,"",(I9-J9)/ABS(J9)),"") | Y9: =IF(T9="Advisory","No pass mark",IF(T9="Manual","Claude will check",IF(I9="","Not done yet",IF(T9="Exact",IF(AND(ISNUMBER(I9),ISNUMBER(J9)),IF(ROUND(I9,2)=ROUND(J9,2),"Pass","Fail"),IF(TRIM(LOWER(I9&""))=TRIM(LOWER(J9&"")),"Pass","Fail")),IF(T9="Min",IF(I9>=U9-1E-9,"Pass","Fail"),IF(T9="Between",IF(AND(I9>=U9,I9<=V9),"Pass","Fail"),IF(J9="","Not done yet",IF(T9="±%",IF(X9="","Check correct answer",IF(ABS(X9)*100<=V9+1E-9,"Pass","Fail")),IF(T9="% range",IF(X9="","Check correct answer",IF(AND(X9*100>=U9-1E-9,X9*100<=V9+1E-9),"Pass","Fail")),IF(T9="±abs",IF(ABS(W9)<=V9+1E-9,"Pass","Fail"),"Check type"))))))))))
A10: S1-004 | B10: A | C10: Map source | D10: Plot 4: app reading matches saved Google reply | E10: Yes/No | F10: Book | G10: Saved Google API reply file | H10: Same as correct answer | J10: Yes | L10: =IF(W10="","",W10) | M10: =IF(O10<>"",O10,Y10) | R10: — | S10: n/a | T10: Exact | W10: =IF(AND(ISNUMBER(I10),ISNUMBER(J10)),I10-J10,"") | X10: =IF(AND(ISNUMBER(I10),ISNUMBER(J10)),IF(J10=0,"",(I10-J10)/ABS(J10)),"") | Y10: =IF(T10="Advisory","No pass mark",IF(T10="Manual","Claude will check",IF(I10="","Not done yet",IF(T10="Exact",IF(AND(ISNUMBER(I10),ISNUMBER(J10)),IF(ROUND(I10,2)=ROUND(J10,2),"Pass","Fail"),IF(TRIM(LOWER(I10&""))=TRIM(LOWER(J10&"")),"Pass","Fail")),IF(T10="Min",IF(I10>=U10-1E-9,"Pass","Fail"),IF(T10="Between",IF(AND(I10>=U10,I10<=V10),"Pass","Fail"),IF(J10="","Not done yet",IF(T10="±%",IF(X10="","Check correct answer",IF(ABS(X10)*100<=V10+1E-9,"Pass","Fail")),IF(T10="% range",IF(X10="","Check correct answer",IF(AND(X10*100>=U10-1E-9,X10*100<=V10+1E-9),"Pass","Fail")),IF(T10="±abs",IF(ABS(W10)<=V10+1E-9,"Pass","Fail"),"Check type"))))))))))
A11: S1-005 | B11: A | C11: Map source | D11: Plot 5: app reading matches saved Google reply | E11: Yes/No | F11: Book | G11: Saved Google API reply file | H11: Same as correct answer | J11: Yes | L11: =IF(W11="","",W11) | M11: =IF(O11<>"",O11,Y11) | R11: — | S11: n/a | T11: Exact | W11: =IF(AND(ISNUMBER(I11),ISNUMBER(J11)),I11-J11,"") | X11: =IF(AND(ISNUMBER(I11),ISNUMBER(J11)),IF(J11=0,"",(I11-J11)/ABS(J11)),"") | Y11: =IF(T11="Advisory","No pass mark",IF(T11="Manual","Claude will check",IF(I11="","Not done yet",IF(T11="Exact",IF(AND(ISNUMBER(I11),ISNUMBER(J11)),IF(ROUND(I11,2)=ROUND(J11,2),"Pass","Fail"),IF(TRIM(LOWER(I11&""))=TRIM(LOWER(J11&"")),"Pass","Fail")),IF(T11="Min",IF(I11>=U11-1E-9,"Pass","Fail"),IF(T11="Between",IF(AND(I11>=U11,I11<=V11),"Pass","Fail"),IF(J11="","Not done yet",IF(T11="±%",IF(X11="","Check correct answer",IF(ABS(X11)*100<=V11+1E-9,"Pass","Fail")),IF(T11="% range",IF(X11="","Check correct answer",IF(AND(X11*100>=U11-1E-9,X11*100<=V11+1E-9),"Pass","Fail")),IF(T11="±abs",IF(ABS(W11)<=V11+1E-9,"Pass","Fail"),"Check type"))))))))))
A12: S1-006 | B12: A | C12: Map source | D12: Plot 6: app reading matches saved Google reply | E12: Yes/No | F12: Book | G12: Saved Google API reply file | H12: Same as correct answer | J12: Yes | L12: =IF(W12="","",W12) | M12: =IF(O12<>"",O12,Y12) | R12: — | S12: n/a | T12: Exact | W12: =IF(AND(ISNUMBER(I12),ISNUMBER(J12)),I12-J12,"") | X12: =IF(AND(ISNUMBER(I12),ISNUMBER(J12)),IF(J12=0,"",(I12-J12)/ABS(J12)),"") | Y12: =IF(T12="Advisory","No pass mark",IF(T12="Manual","Claude will check",IF(I12="","Not done yet",IF(T12="Exact",IF(AND(ISNUMBER(I12),ISNUMBER(J12)),IF(ROUND(I12,2)=ROUND(J12,2),"Pass","Fail"),IF(TRIM(LOWER(I12&""))=TRIM(LOWER(J12&"")),"Pass","Fail")),IF(T12="Min",IF(I12>=U12-1E-9,"Pass","Fail"),IF(T12="Between",IF(AND(I12>=U12,I12<=V12),"Pass","Fail"),IF(J12="","Not done yet",IF(T12="±%",IF(X12="","Check correct answer",IF(ABS(X12)*100<=V12+1E-9,"Pass","Fail")),IF(T12="% range",IF(X12="","Check correct answer",IF(AND(X12*100>=U12-1E-9,X12*100<=V12+1E-9),"Pass","Fail")),IF(T12="±abs",IF(ABS(W12)<=V12+1E-9,"Pass","Fail"),"Check type"))))))))))
A13: S1-007 | B13: A | C13: Map source | D13: Plot 7: app reading matches saved Google reply | E13: Yes/No | F13: Book | G13: Saved Google API reply file | H13: Same as correct answer | J13: Yes | L13: =IF(W13="","",W13) | M13: =IF(O13<>"",O13,Y13) | R13: — | S13: n/a | T13: Exact | W13: =IF(AND(ISNUMBER(I13),ISNUMBER(J13)),I13-J13,"") | X13: =IF(AND(ISNUMBER(I13),ISNUMBER(J13)),IF(J13=0,"",(I13-J13)/ABS(J13)),"") | Y13: =IF(T13="Advisory","No pass mark",IF(T13="Manual","Claude will check",IF(I13="","Not done yet",IF(T13="Exact",IF(AND(ISNUMBER(I13),ISNUMBER(J13)),IF(ROUND(I13,2)=ROUND(J13,2),"Pass","Fail"),IF(TRIM(LOWER(I13&""))=TRIM(LOWER(J13&"")),"Pass","Fail")),IF(T13="Min",IF(I13>=U13-1E-9,"Pass","Fail"),IF(T13="Between",IF(AND(I13>=U13,I13<=V13),"Pass","Fail"),IF(J13="","Not done yet",IF(T13="±%",IF(X13="","Check correct answer",IF(ABS(X13)*100<=V13+1E-9,"Pass","Fail")),IF(T13="% range",IF(X13="","Check correct answer",IF(AND(X13*100>=U13-1E-9,X13*100<=V13+1E-9),"Pass","Fail")),IF(T13="±abs",IF(ABS(W13)<=V13+1E-9,"Pass","Fail"),"Check type"))))))))))
A14: S1-008 | B14: A | C14: Map source | D14: Plot 8: app reading matches saved Google reply | E14: Yes/No | F14: Book | G14: Saved Google API reply file | H14: Same as correct answer | J14: Yes | L14: =IF(W14="","",W14) | M14: =IF(O14<>"",O14,Y14) | R14: — | S14: n/a | T14: Exact | W14: =IF(AND(ISNUMBER(I14),ISNUMBER(J14)),I14-J14,"") | X14: =IF(AND(ISNUMBER(I14),ISNUMBER(J14)),IF(J14=0,"",(I14-J14)/ABS(J14)),"") | Y14: =IF(T14="Advisory","No pass mark",IF(T14="Manual","Claude will check",IF(I14="","Not done yet",IF(T14="Exact",IF(AND(ISNUMBER(I14),ISNUMBER(J14)),IF(ROUND(I14,2)=ROUND(J14,2),"Pass","Fail"),IF(TRIM(LOWER(I14&""))=TRIM(LOWER(J14&"")),"Pass","Fail")),IF(T14="Min",IF(I14>=U14-1E-9,"Pass","Fail"),IF(T14="Between",IF(AND(I14>=U14,I14<=V14),"Pass","Fail"),IF(J14="","Not done yet",IF(T14="±%",IF(X14="","Check correct answer",IF(ABS(X14)*100<=V14+1E-9,"Pass","Fail")),IF(T14="% range",IF(X14="","Check correct answer",IF(AND(X14*100>=U14-1E-9,X14*100<=V14+1E-9),"Pass","Fail")),IF(T14="±abs",IF(ABS(W14)<=V14+1E-9,"Pass","Fail"),"Check type"))))))))))
A15: S1-009 | B15: A | C15: Map source | D15: Plot 9: app reading matches saved Google reply | E15: Yes/No | F15: Book | G15: Saved Google API reply file | H15: Same as correct answer | J15: Yes | L15: =IF(W15="","",W15) | M15: =IF(O15<>"",O15,Y15) | R15: — | S15: n/a | T15: Exact | W15: =IF(AND(ISNUMBER(I15),ISNUMBER(J15)),I15-J15,"") | X15: =IF(AND(ISNUMBER(I15),ISNUMBER(J15)),IF(J15=0,"",(I15-J15)/ABS(J15)),"") | Y15: =IF(T15="Advisory","No pass mark",IF(T15="Manual","Claude will check",IF(I15="","Not done yet",IF(T15="Exact",IF(AND(ISNUMBER(I15),ISNUMBER(J15)),IF(ROUND(I15,2)=ROUND(J15,2),"Pass","Fail"),IF(TRIM(LOWER(I15&""))=TRIM(LOWER(J15&"")),"Pass","Fail")),IF(T15="Min",IF(I15>=U15-1E-9,"Pass","Fail"),IF(T15="Between",IF(AND(I15>=U15,I15<=V15),"Pass","Fail"),IF(J15="","Not done yet",IF(T15="±%",IF(X15="","Check correct answer",IF(ABS(X15)*100<=V15+1E-9,"Pass","Fail")),IF(T15="% range",IF(X15="","Check correct answer",IF(AND(X15*100>=U15-1E-9,X15*100<=V15+1E-9),"Pass","Fail")),IF(T15="±abs",IF(ABS(W15)<=V15+1E-9,"Pass","Fail"),"Check type"))))))))))
A16: S1-010 | B16: A | C16: Map source | D16: Plot 10: app reading matches saved Google reply | E16: Yes/No | F16: Book | G16: Saved Google API reply file | H16: Same as correct answer | J16: Yes | L16: =IF(W16="","",W16) | M16: =IF(O16<>"",O16,Y16) | R16: — | S16: n/a | T16: Exact | W16: =IF(AND(ISNUMBER(I16),ISNUMBER(J16)),I16-J16,"") | X16: =IF(AND(ISNUMBER(I16),ISNUMBER(J16)),IF(J16=0,"",(I16-J16)/ABS(J16)),"") | Y16: =IF(T16="Advisory","No pass mark",IF(T16="Manual","Claude will check",IF(I16="","Not done yet",IF(T16="Exact",IF(AND(ISNUMBER(I16),ISNUMBER(J16)),IF(ROUND(I16,2)=ROUND(J16,2),"Pass","Fail"),IF(TRIM(LOWER(I16&""))=TRIM(LOWER(J16&"")),"Pass","Fail")),IF(T16="Min",IF(I16>=U16-1E-9,"Pass","Fail"),IF(T16="Between",IF(AND(I16>=U16,I16<=V16),"Pass","Fail"),IF(J16="","Not done yet",IF(T16="±%",IF(X16="","Check correct answer",IF(ABS(X16)*100<=V16+1E-9,"Pass","Fail")),IF(T16="% range",IF(X16="","Check correct answer",IF(AND(X16*100>=U16-1E-9,X16*100<=V16+1E-9),"Pass","Fail")),IF(T16="±abs",IF(ABS(W16)<=V16+1E-9,"Pass","Fail"),"Check type"))))))))))
A17: S1-011 | B17: A | C17: Map source | D17: OpenStreetMap takes over with the API key removed | E17: Yes/No | F17: Book | G17: App run without key | H17: Same as correct answer | J17: Yes | L17: =IF(W17="","",W17) | M17: =IF(O17<>"",O17,Y17) | R17: — | S17: n/a | T17: Exact | W17: =IF(AND(ISNUMBER(I17),ISNUMBER(J17)),I17-J17,"") | X17: =IF(AND(ISNUMBER(I17),ISNUMBER(J17)),IF(J17=0,"",(I17-J17)/ABS(J17)),"") | Y17: =IF(T17="Advisory","No pass mark",IF(T17="Manual","Claude will check",IF(I17="","Not done yet",IF(T17="Exact",IF(AND(ISNUMBER(I17),ISNUMBER(J17)),IF(ROUND(I17,2)=ROUND(J17,2),"Pass","Fail"),IF(TRIM(LOWER(I17&""))=TRIM(LOWER(J17&"")),"Pass","Fail")),IF(T17="Min",IF(I17>=U17-1E-9,"Pass","Fail"),IF(T17="Between",IF(AND(I17>=U17,I17<=V17),"Pass","Fail"),IF(J17="","Not done yet",IF(T17="±%",IF(X17="","Check correct answer",IF(ABS(X17)*100<=V17+1E-9,"Pass","Fail")),IF(T17="% range",IF(X17="","Check correct answer",IF(AND(X17*100>=U17-1E-9,X17*100<=V17+1E-9),"Pass","Fail")),IF(T17="±abs",IF(ABS(W17)<=V17+1E-9,"Pass","Fail"),"Check type"))))))))))
A18: S1-012 | B18: A | C18: Map source | D18: Plot 1: 14 Phase I metrics re-run → Enter metrics passed out of 14; list failed metrics here | E18: metrics passed | F18: Real | G18: Phase I references | H18: Same pass marks as Phase I | M18: =IF(O18<>"",O18,Y18) | R18: Phase I | S18: n/a | T18: Manual | W18: =IF(AND(ISNUMBER(I18),ISNUMBER(J18)),I18-J18,"") | X18: =IF(AND(ISNUMBER(I18),ISNUMBER(J18)),IF(J18=0,"",(I18-J18)/ABS(J18)),"") | Y18: =IF(T18="Advisory","No pass mark",IF(T18="Manual","Claude will check",IF(I18="","Not done yet",IF(T18="Exact",IF(AND(ISNUMBER(I18),ISNUMBER(J18)),IF(ROUND(I18,2)=ROUND(J18,2),"Pass","Fail"),IF(TRIM(LOWER(I18&""))=TRIM(LOWER(J18&"")),"Pass","Fail")),IF(T18="Min",IF(I18>=U18-1E-9,"Pass","Fail"),IF(T18="Between",IF(AND(I18>=U18,I18<=V18),"Pass","Fail"),IF(J18="","Not done yet",IF(T18="±%",IF(X18="","Check correct answer",IF(ABS(X18)*100<=V18+1E-9,"Pass","Fail")),IF(T18="% range",IF(X18="","Check correct answer",IF(AND(X18*100>=U18-1E-9,X18*100<=V18+1E-9),"Pass","Fail")),IF(T18="±abs",IF(ABS(W18)<=V18+1E-9,"Pass","Fail"),"Check type"))))))))))
A19: S1-013 | B19: A | C19: Map source | D19: Plot 2: 14 Phase I metrics re-run → Enter metrics passed out of 14; list failed metrics here | E19: metrics passed | F19: Real | G19: Phase I references | H19: Same pass marks as Phase I | M19: =IF(O19<>"",O19,Y19) | R19: Phase I | S19: n/a | T19: Manual | W19: =IF(AND(ISNUMBER(I19),ISNUMBER(J19)),I19-J19,"") | X19: =IF(AND(ISNUMBER(I19),ISNUMBER(J19)),IF(J19=0,"",(I19-J19)/ABS(J19)),"") | Y19: =IF(T19="Advisory","No pass mark",IF(T19="Manual","Claude will check",IF(I19="","Not done yet",IF(T19="Exact",IF(AND(ISNUMBER(I19),ISNUMBER(J19)),IF(ROUND(I19,2)=ROUND(J19,2),"Pass","Fail"),IF(TRIM(LOWER(I19&""))=TRIM(LOWER(J19&"")),"Pass","Fail")),IF(T19="Min",IF(I19>=U19-1E-9,"Pass","Fail"),IF(T19="Between",IF(AND(I19>=U19,I19<=V19),"Pass","Fail"),IF(J19="","Not done yet",IF(T19="±%",IF(X19="","Check correct answer",IF(ABS(X19)*100<=V19+1E-9,"Pass","Fail")),IF(T19="% range",IF(X19="","Check correct answer",IF(AND(X19*100>=U19-1E-9,X19*100<=V19+1E-9),"Pass","Fail")),IF(T19="±abs",IF(ABS(W19)<=V19+1E-9,"Pass","Fail"),"Check type"))))))))))
A20: S1-014 | B20: A | C20: Map source | D20: Plot 3: 14 Phase I metrics re-run → Enter metrics passed out of 14; list failed metrics here | E20: metrics passed | F20: Real | G20: Phase I references | H20: Same pass marks as Phase I | M20: =IF(O20<>"",O20,Y20) | R20: Phase I | S20: n/a | T20: Manual | W20: =IF(AND(ISNUMBER(I20),ISNUMBER(J20)),I20-J20,"") | X20: =IF(AND(ISNUMBER(I20),ISNUMBER(J20)),IF(J20=0,"",(I20-J20)/ABS(J20)),"") | Y20: =IF(T20="Advisory","No pass mark",IF(T20="Manual","Claude will check",IF(I20="","Not done yet",IF(T20="Exact",IF(AND(ISNUMBER(I20),ISNUMBER(J20)),IF(ROUND(I20,2)=ROUND(J20,2),"Pass","Fail"),IF(TRIM(LOWER(I20&""))=TRIM(LOWER(J20&"")),"Pass","Fail")),IF(T20="Min",IF(I20>=U20-1E-9,"Pass","Fail"),IF(T20="Between",IF(AND(I20>=U20,I20<=V20),"Pass","Fail"),IF(J20="","Not done yet",IF(T20="±%",IF(X20="","Check correct answer",IF(ABS(X20)*100<=V20+1E-9,"Pass","Fail")),IF(T20="% range",IF(X20="","Check correct answer",IF(AND(X20*100>=U20-1E-9,X20*100<=V20+1E-9),"Pass","Fail")),IF(T20="±abs",IF(ABS(W20)<=V20+1E-9,"Pass","Fail"),"Check type"))))))))))
A21: S1-015 | B21: A | C21: Map source | D21: Plot 4: 14 Phase I metrics re-run → Enter metrics passed out of 14; list failed metrics here | E21: metrics passed | F21: Real | G21: Phase I references | H21: Same pass marks as Phase I | M21: =IF(O21<>"",O21,Y21) | R21: Phase I | S21: n/a | T21: Manual | W21: =IF(AND(ISNUMBER(I21),ISNUMBER(J21)),I21-J21,"") | X21: =IF(AND(ISNUMBER(I21),ISNUMBER(J21)),IF(J21=0,"",(I21-J21)/ABS(J21)),"") | Y21: =IF(T21="Advisory","No pass mark",IF(T21="Manual","Claude will check",IF(I21="","Not done yet",IF(T21="Exact",IF(AND(ISNUMBER(I21),ISNUMBER(J21)),IF(ROUND(I21,2)=ROUND(J21,2),"Pass","Fail"),IF(TRIM(LOWER(I21&""))=TRIM(LOWER(J21&"")),"Pass","Fail")),IF(T21="Min",IF(I21>=U21-1E-9,"Pass","Fail"),IF(T21="Between",IF(AND(I21>=U21,I21<=V21),"Pass","Fail"),IF(J21="","Not done yet",IF(T21="±%",IF(X21="","Check correct answer",IF(ABS(X21)*100<=V21+1E-9,"Pass","Fail")),IF(T21="% range",IF(X21="","Check correct answer",IF(AND(X21*100>=U21-1E-9,X21*100<=V21+1E-9),"Pass","Fail")),IF(T21="±abs",IF(ABS(W21)<=V21+1E-9,"Pass","Fail"),"Check type"))))))))))
A22: S1-016 | B22: A | C22: Map source | D22: Plot 5: 14 Phase I metrics re-run → Enter metrics passed out of 14; list failed metrics here | E22: metrics passed | F22: Real | G22: Phase I references | H22: Same pass marks as Phase I | M22: =IF(O22<>"",O22,Y22) | R22: Phase I | S22: n/a | T22: Manual | W22: =IF(AND(ISNUMBER(I22),ISNUMBER(J22)),I22-J22,"") | X22: =IF(AND(ISNUMBER(I22),ISNUMBER(J22)),IF(J22=0,"",(I22-J22)/ABS(J22)),"") | Y22: =IF(T22="Advisory","No pass mark",IF(T22="Manual","Claude will check",IF(I22="","Not done yet",IF(T22="Exact",IF(AND(ISNUMBER(I22),ISNUMBER(J22)),IF(ROUND(I22,2)=ROUND(J22,2),"Pass","Fail"),IF(TRIM(LOWER(I22&""))=TRIM(LOWER(J22&"")),"Pass","Fail")),IF(T22="Min",IF(I22>=U22-1E-9,"Pass","Fail"),IF(T22="Between",IF(AND(I22>=U22,I22<=V22),"Pass","Fail"),IF(J22="","Not done yet",IF(T22="±%",IF(X22="","Check correct answer",IF(ABS(X22)*100<=V22+1E-9,"Pass","Fail")),IF(T22="% range",IF(X22="","Check correct answer",IF(AND(X22*100>=U22-1E-9,X22*100<=V22+1E-9),"Pass","Fail")),IF(T22="±abs",IF(ABS(W22)<=V22+1E-9,"Pass","Fail"),"Check type"))))))))))
A23: S1-017 | B23: A | C23: Map source | D23: Plot 6: 14 Phase I metrics re-run → Enter metrics passed out of 14; list failed metrics here | E23: metrics passed | F23: Real | G23: Phase I references | H23: Same pass marks as Phase I | M23: =IF(O23<>"",O23,Y23) | R23: Phase I | S23: n/a | T23: Manual | W23: =IF(AND(ISNUMBER(I23),ISNUMBER(J23)),I23-J23,"") | X23: =IF(AND(ISNUMBER(I23),ISNUMBER(J23)),IF(J23=0,"",(I23-J23)/ABS(J23)),"") | Y23: =IF(T23="Advisory","No pass mark",IF(T23="Manual","Claude will check",IF(I23="","Not done yet",IF(T23="Exact",IF(AND(ISNUMBER(I23),ISNUMBER(J23)),IF(ROUND(I23,2)=ROUND(J23,2),"Pass","Fail"),IF(TRIM(LOWER(I23&""))=TRIM(LOWER(J23&"")),"Pass","Fail")),IF(T23="Min",IF(I23>=U23-1E-9,"Pass","Fail"),IF(T23="Between",IF(AND(I23>=U23,I23<=V23),"Pass","Fail"),IF(J23="","Not done yet",IF(T23="±%",IF(X23="","Check correct answer",IF(ABS(X23)*100<=V23+1E-9,"Pass","Fail")),IF(T23="% range",IF(X23="","Check correct answer",IF(AND(X23*100>=U23-1E-9,X23*100<=V23+1E-9),"Pass","Fail")),IF(T23="±abs",IF(ABS(W23)<=V23+1E-9,"Pass","Fail"),"Check type"))))))))))
A24: S1-018 | B24: A | C24: Map source | D24: Plot 7: 14 Phase I metrics re-run → Enter metrics passed out of 14; list failed metrics here | E24: metrics passed | F24: Real | G24: Phase I references | H24: Same pass marks as Phase I | M24: =IF(O24<>"",O24,Y24) | R24: Phase I | S24: n/a | T24: Manual | W24: =IF(AND(ISNUMBER(I24),ISNUMBER(J24)),I24-J24,"") | X24: =IF(AND(ISNUMBER(I24),ISNUMBER(J24)),IF(J24=0,"",(I24-J24)/ABS(J24)),"") | Y24: =IF(T24="Advisory","No pass mark",IF(T24="Manual","Claude will check",IF(I24="","Not done yet",IF(T24="Exact",IF(AND(ISNUMBER(I24),ISNUMBER(J24)),IF(ROUND(I24,2)=ROUND(J24,2),"Pass","Fail"),IF(TRIM(LOWER(I24&""))=TRIM(LOWER(J24&"")),"Pass","Fail")),IF(T24="Min",IF(I24>=U24-1E-9,"Pass","Fail"),IF(T24="Between",IF(AND(I24>=U24,I24<=V24),"Pass","Fail"),IF(J24="","Not done yet",IF(T24="±%",IF(X24="","Check correct answer",IF(ABS(X24)*100<=V24+1E-9,"Pass","Fail")),IF(T24="% range",IF(X24="","Check correct answer",IF(AND(X24*100>=U24-1E-9,X24*100<=V24+1E-9),"Pass","Fail")),IF(T24="±abs",IF(ABS(W24)<=V24+1E-9,"Pass","Fail"),"Check type"))))))))))
A25: S1-019 | B25: A | C25: Map source | D25: Plot 8: 14 Phase I metrics re-run → Enter metrics passed out of 14; list failed metrics here | E25: metrics passed | F25: Real | G25: Phase I references | H25: Same pass marks as Phase I | M25: =IF(O25<>"",O25,Y25) | R25: Phase I | S25: n/a | T25: Manual | W25: =IF(AND(ISNUMBER(I25),ISNUMBER(J25)),I25-J25,"") | X25: =IF(AND(ISNUMBER(I25),ISNUMBER(J25)),IF(J25=0,"",(I25-J25)/ABS(J25)),"") | Y25: =IF(T25="Advisory","No pass mark",IF(T25="Manual","Claude will check",IF(I25="","Not done yet",IF(T25="Exact",IF(AND(ISNUMBER(I25),ISNUMBER(J25)),IF(ROUND(I25,2)=ROUND(J25,2),"Pass","Fail"),IF(TRIM(LOWER(I25&""))=TRIM(LOWER(J25&"")),"Pass","Fail")),IF(T25="Min",IF(I25>=U25-1E-9,"Pass","Fail"),IF(T25="Between",IF(AND(I25>=U25,I25<=V25),"Pass","Fail"),IF(J25="","Not done yet",IF(T25="±%",IF(X25="","Check correct answer",IF(ABS(X25)*100<=V25+1E-9,"Pass","Fail")),IF(T25="% range",IF(X25="","Check correct answer",IF(AND(X25*100>=U25-1E-9,X25*100<=V25+1E-9),"Pass","Fail")),IF(T25="±abs",IF(ABS(W25)<=V25+1E-9,"Pass","Fail"),"Check type"))))))))))
A26: S1-020 | B26: A | C26: Map source | D26: Plot 9: 14 Phase I metrics re-run → Enter metrics passed out of 14; list failed metrics here | E26: metrics passed | F26: Real | G26: Phase I references | H26: Same pass marks as Phase I | M26: =IF(O26<>"",O26,Y26) | R26: Phase I | S26: n/a | T26: Manual | W26: =IF(AND(ISNUMBER(I26),ISNUMBER(J26)),I26-J26,"") | X26: =IF(AND(ISNUMBER(I26),ISNUMBER(J26)),IF(J26=0,"",(I26-J26)/ABS(J26)),"") | Y26: =IF(T26="Advisory","No pass mark",IF(T26="Manual","Claude will check",IF(I26="","Not done yet",IF(T26="Exact",IF(AND(ISNUMBER(I26),ISNUMBER(J26)),IF(ROUND(I26,2)=ROUND(J26,2),"Pass","Fail"),IF(TRIM(LOWER(I26&""))=TRIM(LOWER(J26&"")),"Pass","Fail")),IF(T26="Min",IF(I26>=U26-1E-9,"Pass","Fail"),IF(T26="Between",IF(AND(I26>=U26,I26<=V26),"Pass","Fail"),IF(J26="","Not done yet",IF(T26="±%",IF(X26="","Check correct answer",IF(ABS(X26)*100<=V26+1E-9,"Pass","Fail")),IF(T26="% range",IF(X26="","Check correct answer",IF(AND(X26*100>=U26-1E-9,X26*100<=V26+1E-9),"Pass","Fail")),IF(T26="±abs",IF(ABS(W26)<=V26+1E-9,"Pass","Fail"),"Check type"))))))))))
A27: S1-021 | B27: A | C27: Map source | D27: Plot 10: 14 Phase I metrics re-run → Enter metrics passed out of 14; list failed metrics here | E27: metrics passed | F27: Real | G27: Phase I references | H27: Same pass marks as Phase I | M27: =IF(O27<>"",O27,Y27) | R27: Phase I | S27: n/a | T27: Manual | W27: =IF(AND(ISNUMBER(I27),ISNUMBER(J27)),I27-J27,"") | X27: =IF(AND(ISNUMBER(I27),ISNUMBER(J27)),IF(J27=0,"",(I27-J27)/ABS(J27)),"") | Y27: =IF(T27="Advisory","No pass mark",IF(T27="Manual","Claude will check",IF(I27="","Not done yet",IF(T27="Exact",IF(AND(ISNUMBER(I27),ISNUMBER(J27)),IF(ROUND(I27,2)=ROUND(J27,2),"Pass","Fail"),IF(TRIM(LOWER(I27&""))=TRIM(LOWER(J27&"")),"Pass","Fail")),IF(T27="Min",IF(I27>=U27-1E-9,"Pass","Fail"),IF(T27="Between",IF(AND(I27>=U27,I27<=V27),"Pass","Fail"),IF(J27="","Not done yet",IF(T27="±%",IF(X27="","Check correct answer",IF(ABS(X27)*100<=V27+1E-9,"Pass","Fail")),IF(T27="% range",IF(X27="","Check correct answer",IF(AND(X27*100>=U27-1E-9,X27*100<=V27+1E-9),"Pass","Fail")),IF(T27="±abs",IF(ABS(W27)<=V27+1E-9,"Pass","Fail"),"Check type"))))))))))
B28: B's tests (15)
A29: S1-022 | B29: B | C29: Height search | D29: Plot 1: height within road-width cap and FAR | E29: Yes/No | F29: Book | G29: Rule | H29: Same as correct answer | J29: Yes | L29: =IF(W29="","",W29) | M29: =IF(O29<>"",O29,Y29) | R29: Bye-law height and FAR limits | S29: n/a | T29: Exact | W29: =IF(AND(ISNUMBER(I29),ISNUMBER(J29)),I29-J29,"") | X29: =IF(AND(ISNUMBER(I29),ISNUMBER(J29)),IF(J29=0,"",(I29-J29)/ABS(J29)),"") | Y29: =IF(T29="Advisory","No pass mark",IF(T29="Manual","Claude will check",IF(I29="","Not done yet",IF(T29="Exact",IF(AND(ISNUMBER(I29),ISNUMBER(J29)),IF(ROUND(I29,2)=ROUND(J29,2),"Pass","Fail"),IF(TRIM(LOWER(I29&""))=TRIM(LOWER(J29&"")),"Pass","Fail")),IF(T29="Min",IF(I29>=U29-1E-9,"Pass","Fail"),IF(T29="Between",IF(AND(I29>=U29,I29<=V29),"Pass","Fail"),IF(J29="","Not done yet",IF(T29="±%",IF(X29="","Check correct answer",IF(ABS(X29)*100<=V29+1E-9,"Pass","Fail")),IF(T29="% range",IF(X29="","Check correct answer",IF(AND(X29*100>=U29-1E-9,X29*100<=V29+1E-9),"Pass","Fail")),IF(T29="±abs",IF(ABS(W29)<=V29+1E-9,"Pass","Fail"),"Check type"))))))))))
A30: S1-023 | B30: B | C30: Height search | D30: Plot 2: height within road-width cap and FAR | E30: Yes/No | F30: Book | G30: Rule | H30: Same as correct answer | J30: Yes | L30: =IF(W30="","",W30) | M30: =IF(O30<>"",O30,Y30) | R30: Bye-law height and FAR limits | S30: n/a | T30: Exact | W30: =IF(AND(ISNUMBER(I30),ISNUMBER(J30)),I30-J30,"") | X30: =IF(AND(ISNUMBER(I30),ISNUMBER(J30)),IF(J30=0,"",(I30-J30)/ABS(J30)),"") | Y30: =IF(T30="Advisory","No pass mark",IF(T30="Manual","Claude will check",IF(I30="","Not done yet",IF(T30="Exact",IF(AND(ISNUMBER(I30),ISNUMBER(J30)),IF(ROUND(I30,2)=ROUND(J30,2),"Pass","Fail"),IF(TRIM(LOWER(I30&""))=TRIM(LOWER(J30&"")),"Pass","Fail")),IF(T30="Min",IF(I30>=U30-1E-9,"Pass","Fail"),IF(T30="Between",IF(AND(I30>=U30,I30<=V30),"Pass","Fail"),IF(J30="","Not done yet",IF(T30="±%",IF(X30="","Check correct answer",IF(ABS(X30)*100<=V30+1E-9,"Pass","Fail")),IF(T30="% range",IF(X30="","Check correct answer",IF(AND(X30*100>=U30-1E-9,X30*100<=V30+1E-9),"Pass","Fail")),IF(T30="±abs",IF(ABS(W30)<=V30+1E-9,"Pass","Fail"),"Check type"))))))))))
A31: S1-024 | B31: B | C31: Height search | D31: Plot 3: height within road-width cap and FAR | E31: Yes/No | F31: Book | G31: Rule | H31: Same as correct answer | J31: Yes | L31: =IF(W31="","",W31) | M31: =IF(O31<>"",O31,Y31) | R31: Bye-law height and FAR limits | S31: n/a | T31: Exact | W31: =IF(AND(ISNUMBER(I31),ISNUMBER(J31)),I31-J31,"") | X31: =IF(AND(ISNUMBER(I31),ISNUMBER(J31)),IF(J31=0,"",(I31-J31)/ABS(J31)),"") | Y31: =IF(T31="Advisory","No pass mark",IF(T31="Manual","Claude will check",IF(I31="","Not done yet",IF(T31="Exact",IF(AND(ISNUMBER(I31),ISNUMBER(J31)),IF(ROUND(I31,2)=ROUND(J31,2),"Pass","Fail"),IF(TRIM(LOWER(I31&""))=TRIM(LOWER(J31&"")),"Pass","Fail")),IF(T31="Min",IF(I31>=U31-1E-9,"Pass","Fail"),IF(T31="Between",IF(AND(I31>=U31,I31<=V31),"Pass","Fail"),IF(J31="","Not done yet",IF(T31="±%",IF(X31="","Check correct answer",IF(ABS(X31)*100<=V31+1E-9,"Pass","Fail")),IF(T31="% range",IF(X31="","Check correct answer",IF(AND(X31*100>=U31-1E-9,X31*100<=V31+1E-9),"Pass","Fail")),IF(T31="±abs",IF(ABS(W31)<=V31+1E-9,"Pass","Fail"),"Check type"))))))))))
A32: S1-025 | B32: B | C32: Height search | D32: Plot 4: height within road-width cap and FAR | E32: Yes/No | F32: Book | G32: Rule | H32: Same as correct answer | J32: Yes | L32: =IF(W32="","",W32) | M32: =IF(O32<>"",O32,Y32) | R32: Bye-law height and FAR limits | S32: n/a | T32: Exact | W32: =IF(AND(ISNUMBER(I32),ISNUMBER(J32)),I32-J32,"") | X32: =IF(AND(ISNUMBER(I32),ISNUMBER(J32)),IF(J32=0,"",(I32-J32)/ABS(J32)),"") | Y32: =IF(T32="Advisory","No pass mark",IF(T32="Manual","Claude will check",IF(I32="","Not done yet",IF(T32="Exact",IF(AND(ISNUMBER(I32),ISNUMBER(J32)),IF(ROUND(I32,2)=ROUND(J32,2),"Pass","Fail"),IF(TRIM(LOWER(I32&""))=TRIM(LOWER(J32&"")),"Pass","Fail")),IF(T32="Min",IF(I32>=U32-1E-9,"Pass","Fail"),IF(T32="Between",IF(AND(I32>=U32,I32<=V32),"Pass","Fail"),IF(J32="","Not done yet",IF(T32="±%",IF(X32="","Check correct answer",IF(ABS(X32)*100<=V32+1E-9,"Pass","Fail")),IF(T32="% range",IF(X32="","Check correct answer",IF(AND(X32*100>=U32-1E-9,X32*100<=V32+1E-9),"Pass","Fail")),IF(T32="±abs",IF(ABS(W32)<=V32+1E-9,"Pass","Fail"),"Check type"))))))))))
A33: S1-026 | B33: B | C33: Height search | D33: Plot 5: height within road-width cap and FAR | E33: Yes/No | F33: Book | G33: Rule | H33: Same as correct answer | J33: Yes | L33: =IF(W33="","",W33) | M33: =IF(O33<>"",O33,Y33) | R33: Bye-law height and FAR limits | S33: n/a | T33: Exact | W33: =IF(AND(ISNUMBER(I33),ISNUMBER(J33)),I33-J33,"") | X33: =IF(AND(ISNUMBER(I33),ISNUMBER(J33)),IF(J33=0,"",(I33-J33)/ABS(J33)),"") | Y33: =IF(T33="Advisory","No pass mark",IF(T33="Manual","Claude will check",IF(I33="","Not done yet",IF(T33="Exact",IF(AND(ISNUMBER(I33),ISNUMBER(J33)),IF(ROUND(I33,2)=ROUND(J33,2),"Pass","Fail"),IF(TRIM(LOWER(I33&""))=TRIM(LOWER(J33&"")),"Pass","Fail")),IF(T33="Min",IF(I33>=U33-1E-9,"Pass","Fail"),IF(T33="Between",IF(AND(I33>=U33,I33<=V33),"Pass","Fail"),IF(J33="","Not done yet",IF(T33="±%",IF(X33="","Check correct answer",IF(ABS(X33)*100<=V33+1E-9,"Pass","Fail")),IF(T33="% range",IF(X33="","Check correct answer",IF(AND(X33*100>=U33-1E-9,X33*100<=V33+1E-9),"Pass","Fail")),IF(T33="±abs",IF(ABS(W33)<=V33+1E-9,"Pass","Fail"),"Check type"))))))))))
A34: S1-027 | B34: B | C34: Height search | D34: Plot 6: height within road-width cap and FAR | E34: Yes/No | F34: Book | G34: Rule | H34: Same as correct answer | J34: Yes | L34: =IF(W34="","",W34) | M34: =IF(O34<>"",O34,Y34) | R34: Bye-law height and FAR limits | S34: n/a | T34: Exact | W34: =IF(AND(ISNUMBER(I34),ISNUMBER(J34)),I34-J34,"") | X34: =IF(AND(ISNUMBER(I34),ISNUMBER(J34)),IF(J34=0,"",(I34-J34)/ABS(J34)),"") | Y34: =IF(T34="Advisory","No pass mark",IF(T34="Manual","Claude will check",IF(I34="","Not done yet",IF(T34="Exact",IF(AND(ISNUMBER(I34),ISNUMBER(J34)),IF(ROUND(I34,2)=ROUND(J34,2),"Pass","Fail"),IF(TRIM(LOWER(I34&""))=TRIM(LOWER(J34&"")),"Pass","Fail")),IF(T34="Min",IF(I34>=U34-1E-9,"Pass","Fail"),IF(T34="Between",IF(AND(I34>=U34,I34<=V34),"Pass","Fail"),IF(J34="","Not done yet",IF(T34="±%",IF(X34="","Check correct answer",IF(ABS(X34)*100<=V34+1E-9,"Pass","Fail")),IF(T34="% range",IF(X34="","Check correct answer",IF(AND(X34*100>=U34-1E-9,X34*100<=V34+1E-9),"Pass","Fail")),IF(T34="±abs",IF(ABS(W34)<=V34+1E-9,"Pass","Fail"),"Check type"))))))))))
A35: S1-028 | B35: B | C35: Height search | D35: Plot 7: height within road-width cap and FAR | E35: Yes/No | F35: Book | G35: Rule | H35: Same as correct answer | J35: Yes | L35: =IF(W35="","",W35) | M35: =IF(O35<>"",O35,Y35) | R35: Bye-law height and FAR limits | S35: n/a | T35: Exact | W35: =IF(AND(ISNUMBER(I35),ISNUMBER(J35)),I35-J35,"") | X35: =IF(AND(ISNUMBER(I35),ISNUMBER(J35)),IF(J35=0,"",(I35-J35)/ABS(J35)),"") | Y35: =IF(T35="Advisory","No pass mark",IF(T35="Manual","Claude will check",IF(I35="","Not done yet",IF(T35="Exact",IF(AND(ISNUMBER(I35),ISNUMBER(J35)),IF(ROUND(I35,2)=ROUND(J35,2),"Pass","Fail"),IF(TRIM(LOWER(I35&""))=TRIM(LOWER(J35&"")),"Pass","Fail")),IF(T35="Min",IF(I35>=U35-1E-9,"Pass","Fail"),IF(T35="Between",IF(AND(I35>=U35,I35<=V35),"Pass","Fail"),IF(J35="","Not done yet",IF(T35="±%",IF(X35="","Check correct answer",IF(ABS(X35)*100<=V35+1E-9,"Pass","Fail")),IF(T35="% range",IF(X35="","Check correct answer",IF(AND(X35*100>=U35-1E-9,X35*100<=V35+1E-9),"Pass","Fail")),IF(T35="±abs",IF(ABS(W35)<=V35+1E-9,"Pass","Fail"),"Check type"))))))))))
A36: S1-029 | B36: B | C36: Height search | D36: Plot 8: height within road-width cap and FAR | E36: Yes/No | F36: Book | G36: Rule | H36: Same as correct answer | J36: Yes | L36: =IF(W36="","",W36) | M36: =IF(O36<>"",O36,Y36) | R36: Bye-law height and FAR limits | S36: n/a | T36: Exact | W36: =IF(AND(ISNUMBER(I36),ISNUMBER(J36)),I36-J36,"") | X36: =IF(AND(ISNUMBER(I36),ISNUMBER(J36)),IF(J36=0,"",(I36-J36)/ABS(J36)),"") | Y36: =IF(T36="Advisory","No pass mark",IF(T36="Manual","Claude will check",IF(I36="","Not done yet",IF(T36="Exact",IF(AND(ISNUMBER(I36),ISNUMBER(J36)),IF(ROUND(I36,2)=ROUND(J36,2),"Pass","Fail"),IF(TRIM(LOWER(I36&""))=TRIM(LOWER(J36&"")),"Pass","Fail")),IF(T36="Min",IF(I36>=U36-1E-9,"Pass","Fail"),IF(T36="Between",IF(AND(I36>=U36,I36<=V36),"Pass","Fail"),IF(J36="","Not done yet",IF(T36="±%",IF(X36="","Check correct answer",IF(ABS(X36)*100<=V36+1E-9,"Pass","Fail")),IF(T36="% range",IF(X36="","Check correct answer",IF(AND(X36*100>=U36-1E-9,X36*100<=V36+1E-9),"Pass","Fail")),IF(T36="±abs",IF(ABS(W36)<=V36+1E-9,"Pass","Fail"),"Check type"))))))))))
A37: S1-030 | B37: B | C37: Height search | D37: Plot 9: height within road-width cap and FAR | E37: Yes/No | F37: Book | G37: Rule | H37: Same as correct answer | J37: Yes | L37: =IF(W37="","",W37) | M37: =IF(O37<>"",O37,Y37) | R37: Bye-law height and FAR limits | S37: n/a | T37: Exact | W37: =IF(AND(ISNUMBER(I37),ISNUMBER(J37)),I37-J37,"") | X37: =IF(AND(ISNUMBER(I37),ISNUMBER(J37)),IF(J37=0,"",(I37-J37)/ABS(J37)),"") | Y37: =IF(T37="Advisory","No pass mark",IF(T37="Manual","Claude will check",IF(I37="","Not done yet",IF(T37="Exact",IF(AND(ISNUMBER(I37),ISNUMBER(J37)),IF(ROUND(I37,2)=ROUND(J37,2),"Pass","Fail"),IF(TRIM(LOWER(I37&""))=TRIM(LOWER(J37&"")),"Pass","Fail")),IF(T37="Min",IF(I37>=U37-1E-9,"Pass","Fail"),IF(T37="Between",IF(AND(I37>=U37,I37<=V37),"Pass","Fail"),IF(J37="","Not done yet",IF(T37="±%",IF(X37="","Check correct answer",IF(ABS(X37)*100<=V37+1E-9,"Pass","Fail")),IF(T37="% range",IF(X37="","Check correct answer",IF(AND(X37*100>=U37-1E-9,X37*100<=V37+1E-9),"Pass","Fail")),IF(T37="±abs",IF(ABS(W37)<=V37+1E-9,"Pass","Fail"),"Check type"))))))))))
A38: S1-031 | B38: B | C38: Height search | D38: Plot 10: height within road-width cap and FAR | E38: Yes/No | F38: Book | G38: Rule | H38: Same as correct answer | J38: Yes | L38: =IF(W38="","",W38) | M38: =IF(O38<>"",O38,Y38) | R38: Bye-law height and FAR limits | S38: n/a | T38: Exact | W38: =IF(AND(ISNUMBER(I38),ISNUMBER(J38)),I38-J38,"") | X38: =IF(AND(ISNUMBER(I38),ISNUMBER(J38)),IF(J38=0,"",(I38-J38)/ABS(J38)),"") | Y38: =IF(T38="Advisory","No pass mark",IF(T38="Manual","Claude will check",IF(I38="","Not done yet",IF(T38="Exact",IF(AND(ISNUMBER(I38),ISNUMBER(J38)),IF(ROUND(I38,2)=ROUND(J38,2),"Pass","Fail"),IF(TRIM(LOWER(I38&""))=TRIM(LOWER(J38&"")),"Pass","Fail")),IF(T38="Min",IF(I38>=U38-1E-9,"Pass","Fail"),IF(T38="Between",IF(AND(I38>=U38,I38<=V38),"Pass","Fail"),IF(J38="","Not done yet",IF(T38="±%",IF(X38="","Check correct answer",IF(ABS(X38)*100<=V38+1E-9,"Pass","Fail")),IF(T38="% range",IF(X38="","Check correct answer",IF(AND(X38*100>=U38-1E-9,X38*100<=V38+1E-9),"Pass","Fail")),IF(T38="±abs",IF(ABS(W38)<=V38+1E-9,"Pass","Fail"),"Check type"))))))))))
A39: S1-032 | B39: B | C39: Height search | D39: RERA project P1: floors chosen vs sanctioned | E39: floors | F39: Real | G39: Sanctioned plan | H39: Within ±1 floor | L39: =IF(W39="","",W39) | M39: =IF(O39<>"",O39,Y39) | R39: — | S39: n/a | T39: ±abs | V39: 1 | W39: =IF(AND(ISNUMBER(I39),ISNUMBER(J39)),I39-J39,"") | X39: =IF(AND(ISNUMBER(I39),ISNUMBER(J39)),IF(J39=0,"",(I39-J39)/ABS(J39)),"") | Y39: =IF(T39="Advisory","No pass mark",IF(T39="Manual","Claude will check",IF(I39="","Not done yet",IF(T39="Exact",IF(AND(ISNUMBER(I39),ISNUMBER(J39)),IF(ROUND(I39,2)=ROUND(J39,2),"Pass","Fail"),IF(TRIM(LOWER(I39&""))=TRIM(LOWER(J39&"")),"Pass","Fail")),IF(T39="Min",IF(I39>=U39-1E-9,"Pass","Fail"),IF(T39="Between",IF(AND(I39>=U39,I39<=V39),"Pass","Fail"),IF(J39="","Not done yet",IF(T39="±%",IF(X39="","Check correct answer",IF(ABS(X39)*100<=V39+1E-9,"Pass","Fail")),IF(T39="% range",IF(X39="","Check correct answer",IF(AND(X39*100>=U39-1E-9,X39*100<=V39+1E-9),"Pass","Fail")),IF(T39="±abs",IF(ABS(W39)<=V39+1E-9,"Pass","Fail"),"Check type"))))))))))
A40: S1-033 | B40: B | C40: Height search | D40: RERA project P2: floors chosen vs sanctioned | E40: floors | F40: Real | G40: Sanctioned plan | H40: Within ±1 floor | L40: =IF(W40="","",W40) | M40: =IF(O40<>"",O40,Y40) | R40: — | S40: n/a | T40: ±abs | V40: 1 | W40: =IF(AND(ISNUMBER(I40),ISNUMBER(J40)),I40-J40,"") | X40: =IF(AND(ISNUMBER(I40),ISNUMBER(J40)),IF(J40=0,"",(I40-J40)/ABS(J40)),"") | Y40: =IF(T40="Advisory","No pass mark",IF(T40="Manual","Claude will check",IF(I40="","Not done yet",IF(T40="Exact",IF(AND(ISNUMBER(I40),ISNUMBER(J40)),IF(ROUND(I40,2)=ROUND(J40,2),"Pass","Fail"),IF(TRIM(LOWER(I40&""))=TRIM(LOWER(J40&"")),"Pass","Fail")),IF(T40="Min",IF(I40>=U40-1E-9,"Pass","Fail"),IF(T40="Between",IF(AND(I40>=U40,I40<=V40),"Pass","Fail"),IF(J40="","Not done yet",IF(T40="±%",IF(X40="","Check correct answer",IF(ABS(X40)*100<=V40+1E-9,"Pass","Fail")),IF(T40="% range",IF(X40="","Check correct answer",IF(AND(X40*100>=U40-1E-9,X40*100<=V40+1E-9),"Pass","Fail")),IF(T40="±abs",IF(ABS(W40)<=V40+1E-9,"Pass","Fail"),"Check type"))))))))))
A41: S1-034 | B41: B | C41: Height search | D41: RERA project P3: floors chosen vs sanctioned | E41: floors | F41: Real | G41: Sanctioned plan | H41: Within ±1 floor | L41: =IF(W41="","",W41) | M41: =IF(O41<>"",O41,Y41) | R41: — | S41: n/a | T41: ±abs | V41: 1 | W41: =IF(AND(ISNUMBER(I41),ISNUMBER(J41)),I41-J41,"") | X41: =IF(AND(ISNUMBER(I41),ISNUMBER(J41)),IF(J41=0,"",(I41-J41)/ABS(J41)),"") | Y41: =IF(T41="Advisory","No pass mark",IF(T41="Manual","Claude will check",IF(I41="","Not done yet",IF(T41="Exact",IF(AND(ISNUMBER(I41),ISNUMBER(J41)),IF(ROUND(I41,2)=ROUND(J41,2),"Pass","Fail"),IF(TRIM(LOWER(I41&""))=TRIM(LOWER(J41&"")),"Pass","Fail")),IF(T41="Min",IF(I41>=U41-1E-9,"Pass","Fail"),IF(T41="Between",IF(AND(I41>=U41,I41<=V41),"Pass","Fail"),IF(J41="","Not done yet",IF(T41="±%",IF(X41="","Check correct answer",IF(ABS(X41)*100<=V41+1E-9,"Pass","Fail")),IF(T41="% range",IF(X41="","Check correct answer",IF(AND(X41*100>=U41-1E-9,X41*100<=V41+1E-9),"Pass","Fail")),IF(T41="±abs",IF(ABS(W41)<=V41+1E-9,"Pass","Fail"),"Check type"))))))))))
...

Sheet Stage 2
A1: Stage 2 Design (weeks 3 to 4)
A2: HOW TO FILL: 1) Find your letter. 2) Run the test in the app and type its answer in App answer. 3) Type the correct answer from the book or RERA in Correct answer (some are already filled). 4) Write where you got it. 5) Result fills itself. Don't change grey cells.
A4: Yellow = you fill · Grey = fixed plan, don't change · Blue = Claude fills · Click + above column R to see technical details
A5: # | B5: Who | C5: Topic | D5: What to test | E5: Unit | F5: Type | G5: Compare with | H5: Pass if | I5: App answer | J5: Correct answer | K5: Where you got it (book + page, or RERA no.) | L5: Off by | M5: Result | N5: Notes | O5: Claude: override | P5: Claude: first-run result | Q5: Claude: why it failed | R5: Code / clause | S5: Edition | T5: Tol type | U5: Tol low | V5: Tol high | W5: Difference | X5: Error % | Y5: Auto result
B6: A's tests (57)
A7: S2-001 | B7: A | C7: Areas | D7: Hand unit U1: carpet area | E7: m² | F7: Book | G7: Unit drawn by hand with known areas | H7: Within 2% of correct answer | L7: =IF(X7="","",X7) | M7: =IF(O7<>"",O7,Y7) | R7: RERA Act 2016 Sec. 2(k) (carpet) | S7: n/a | T7: ±% | V7: 2 | W7: =IF(AND(ISNUMBER(I7),ISNUMBER(J7)),I7-J7,"") | X7: =IF(AND(ISNUMBER(I7),ISNUMBER(J7)),IF(J7=0,"",(I7-J7)/ABS(J7)),"") | Y7: =IF(T7="Advisory","No pass mark",IF(T7="Manual","Claude will check",IF(I7="","Not done yet",IF(T7="Exact",IF(AND(ISNUMBER(I7),ISNUMBER(J7)),IF(ROUND(I7,2)=ROUND(J7,2),"Pass","Fail"),IF(TRIM(LOWER(I7&""))=TRIM(LOWER(J7&"")),"Pass","Fail")),IF(T7="Min",IF(I7>=U7-1E-9,"Pass","Fail"),IF(T7="Between",IF(AND(I7>=U7,I7<=V7),"Pass","Fail"),IF(J7="","Not done yet",IF(T7="±%",IF(X7="","Check correct answer",IF(ABS(X7)*100<=V7+1E-9,"Pass","Fail")),IF(T7="% range",IF(X7="","Check correct answer",IF(AND(X7*100>=U7-1E-9,X7*100<=V7+1E-9),"Pass","Fail")),IF(T7="±abs",IF(ABS(W7)<=V7+1E-9,"Pass","Fail"),"Check type"))))))))))
A8: S2-002 | B8: A | C8: Areas | D8: Hand unit U1: built-up area | E8: m² | F8: Book | G8: Unit drawn by hand with known areas | H8: Within 2% of correct answer | L8: =IF(X8="","",X8) | M8: =IF(O8<>"",O8,Y8) | R8: RERA Act 2016 Sec. 2(k) (carpet) | S8: n/a | T8: ±% | V8: 2 | W8: =IF(AND(ISNUMBER(I8),ISNUMBER(J8)),I8-J8,"") | X8: =IF(AND(ISNUMBER(I8),ISNUMBER(J8)),IF(J8=0,"",(I8-J8)/ABS(J8)),"") | Y8: =IF(T8="Advisory","No pass mark",IF(T8="Manual","Claude will check",IF(I8="","Not done yet",IF(T8="Exact",IF(AND(ISNUMBER(I8),ISNUMBER(J8)),IF(ROUND(I8,2)=ROUND(J8,2),"Pass","Fail"),IF(TRIM(LOWER(I8&""))=TRIM(LOWER(J8&"")),"Pass","Fail")),IF(T8="Min",IF(I8>=U8-1E-9,"Pass","Fail"),IF(T8="Between",IF(AND(I8>=U8,I8<=V8),"Pass","Fail"),IF(J8="","Not done yet",IF(T8="±%",IF(X8="","Check correct answer",IF(ABS(X8)*100<=V8+1E-9,"Pass","Fail")),IF(T8="% range",IF(X8="","Check correct answer",IF(AND(X8*100>=U8-1E-9,X8*100<=V8+1E-9),"Pass","Fail")),IF(T8="±abs",IF(ABS(W8)<=V8+1E-9,"Pass","Fail"),"Check type"))))))))))
A9: S2-003 | B9: A | C9: Areas | D9: Hand unit U1: super built-up area | E9: m² | F9: Book | G9: Unit drawn by hand with known areas | H9: Within 2% of correct answer | L9: =IF(X9="","",X9) | M9: =IF(O9<>"",O9,Y9) | R9: RERA Act 2016 Sec. 2(k) (carpet) | S9: n/a | T9: ±% | V9: 2 | W9: =IF(AND(ISNUMBER(I9),ISNUMBER(J9)),I9-J9,"") | X9: =IF(AND(ISNUMBER(I9),ISNUMBER(J9)),IF(J9=0,"",(I9-J9)/ABS(J9)),"") | Y9: =IF(T9="Advisory","No pass mark",IF(T9="Manual","Claude will check",IF(I9="","Not done yet",IF(T9="Exact",IF(AND(ISNUMBER(I9),ISNUMBER(J9)),IF(ROUND(I9,2)=ROUND(J9,2),"Pass","Fail"),IF(TRIM(LOWER(I9&""))=TRIM(LOWER(J9&"")),"Pass","Fail")),IF(T9="Min",IF(I9>=U9-1E-9,"Pass","Fail"),IF(T9="Between",IF(AND(I9>=U9,I9<=V9),"Pass","Fail"),IF(J9="","Not done yet",IF(T9="±%",IF(X9="","Check correct answer",IF(ABS(X9)*100<=V9+1E-9,"Pass","Fail")),IF(T9="% range",IF(X9="","Check correct answer",IF(AND(X9*100>=U9-1E-9,X9*100<=V9+1E-9),"Pass","Fail")),IF(T9="±abs",IF(ABS(W9)<=V9+1E-9,"Pass","Fail"),"Check type"))))))))))
A10: S2-004 | B10: A | C10: Areas | D10: Hand unit U2: carpet area | E10: m² | F10: Book | G10: Unit drawn by hand with known areas | H10: Within 2% of correct answer | L10: =IF(X10="","",X10) | M10: =IF(O10<>"",O10,Y10) | R10: RERA Act 2016 Sec. 2(k) (carpet) | S10: n/a | T10: ±% | V10: 2 | W10: =IF(AND(ISNUMBER(I10),ISNUMBER(J10)),I10-J10,"") | X10: =IF(AND(ISNUMBER(I10),ISNUMBER(J10)),IF(J10=0,"",(I10-J10)/ABS(J10)),"") | Y10: =IF(T10="Advisory","No pass mark",IF(T10="Manual","Claude will check",IF(I10="","Not done yet",IF(T10="Exact",IF(AND(ISNUMBER(I10),ISNUMBER(J10)),IF(ROUND(I10,2)=ROUND(J10,2),"Pass","Fail"),IF(TRIM(LOWER(I10&""))=TRIM(LOWER(J10&"")),"Pass","Fail")),IF(T10="Min",IF(I10>=U10-1E-9,"Pass","Fail"),IF(T10="Between",IF(AND(I10>=U10,I10<=V10),"Pass","Fail"),IF(J10="","Not done yet",IF(T10="±%",IF(X10="","Check correct answer",IF(ABS(X10)*100<=V10+1E-9,"Pass","Fail")),IF(T10="% range",IF(X10="","Check correct answer",IF(AND(X10*100>=U10-1E-9,X10*100<=V10+1E-9),"Pass","Fail")),IF(T10="±abs",IF(ABS(W10)<=V10+1E-9,"Pass","Fail"),"Check type"))))))))))
A11: S2-005 | B11: A | C11: Areas | D11: Hand unit U2: built-up area | E11: m² | F11: Book | G11: Unit drawn by hand with known areas | H11: Within 2% of correct answer | L11: =IF(X11="","",X11) | M11: =IF(O11<>"",O11,Y11) | R11: RERA Act 2016 Sec. 2(k) (carpet) | S11: n/a | T11: ±% | V11: 2 | W11: =IF(AND(ISNUMBER(I11),ISNUMBER(J11)),I11-J11,"") | X11: =IF(AND(ISNUMBER(I11),ISNUMBER(J11)),IF(J11=0,"",(I11-J11)/ABS(J11)),"") | Y11: =IF(T11="Advisory","No pass mark",IF(T11="Manual","Claude will check",IF(I11="","Not done yet",IF(T11="Exact",IF(AND(ISNUMBER(I11),ISNUMBER(J11)),IF(ROUND(I11,2)=ROUND(J11,2),"Pass","Fail"),IF(TRIM(LOWER(I11&""))=TRIM(LOWER(J11&"")),"Pass","Fail")),IF(T11="Min",IF(I11>=U11-1E-9,"Pass","Fail"),IF(T11="Between",IF(AND(I11>=U11,I11<=V11),"Pass","Fail"),IF(J11="","Not done yet",IF(T11="±%",IF(X11="","Check correct answer",IF(ABS(X11)*100<=V11+1E-9,"Pass","Fail")),IF(T11="% range",IF(X11="","Check correct answer",IF(AND(X11*100>=U11-1E-9,X11*100<=V11+1E-9),"Pass","Fail")),IF(T11="±abs",IF(ABS(W11)<=V11+1E-9,"Pass","Fail"),"Check type"))))))))))
A12: S2-006 | B12: A | C12: Areas | D12: Hand unit U2: super built-up area | E12: m² | F12: Book | G12: Unit drawn by hand with known areas | H12: Within 2% of correct answer | L12: =IF(X12="","",X12) | M12: =IF(O12<>"",O12,Y12) | R12: RERA Act 2016 Sec. 2(k) (carpet) | S12: n/a | T12: ±% | V12: 2 | W12: =IF(AND(ISNUMBER(I12),ISNUMBER(J12)),I12-J12,"") | X12: =IF(AND(ISNUMBER(I12),ISNUMBER(J12)),IF(J12=0,"",(I12-J12)/ABS(J12)),"") | Y12: =IF(T12="Advisory","No pass mark",IF(T12="Manual","Claude will check",IF(I12="","Not done yet",IF(T12="Exact",IF(AND(ISNUMBER(I12),ISNUMBER(J12)),IF(ROUND(I12,2)=ROUND(J12,2),"Pass","Fail"),IF(TRIM(LOWER(I12&""))=TRIM(LOWER(J12&"")),"Pass","Fail")),IF(T12="Min",IF(I12>=U12-1E-9,"Pass","Fail"),IF(T12="Between",IF(AND(I12>=U12,I12<=V12),"Pass","Fail"),IF(J12="","Not done yet",IF(T12="±%",IF(X12="","Check correct answer",IF(ABS(X12)*100<=V12+1E-9,"Pass","Fail")),IF(T12="% range",IF(X12="","Check correct answer",IF(AND(X12*100>=U12-1E-9,X12*100<=V12+1E-9),"Pass","Fail")),IF(T12="±abs",IF(ABS(W12)<=V12+1E-9,"Pass","Fail"),"Check type"))))))))))
A13: S2-007 | B13: A | C13: Areas | D13: Hand unit U3: carpet area | E13: m² | F13: Book | G13: Unit drawn by hand with known areas | H13: Within 2% of correct answer | L13: =IF(X13="","",X13) | M13: =IF(O13<>"",O13,Y13) | R13: RERA Act 2016 Sec. 2(k) (carpet) | S13: n/a | T13: ±% | V13: 2 | W13: =IF(AND(ISNUMBER(I13),ISNUMBER(J13)),I13-J13,"") | X13: =IF(AND(ISNUMBER(I13),ISNUMBER(J13)),IF(J13=0,"",(I13-J13)/ABS(J13)),"") | Y13: =IF(T13="Advisory","No pass mark",IF(T13="Manual","Claude will check",IF(I13="","Not done yet",IF(T13="Exact",IF(AND(ISNUMBER(I13),ISNUMBER(J13)),IF(ROUND(I13,2)=ROUND(J13,2),"Pass","Fail"),IF(TRIM(LOWER(I13&""))=TRIM(LOWER(J13&"")),"Pass","Fail")),IF(T13="Min",IF(I13>=U13-1E-9,"Pass","Fail"),IF(T13="Between",IF(AND(I13>=U13,I13<=V13),"Pass","Fail"),IF(J13="","Not done yet",IF(T13="±%",IF(X13="","Check correct answer",IF(ABS(X13)*100<=V13+1E-9,"Pass","Fail")),IF(T13="% range",IF(X13="","Check correct answer",IF(AND(X13*100>=U13-1E-9,X13*100<=V13+1E-9),"Pass","Fail")),IF(T13="±abs",IF(ABS(W13)<=V13+1E-9,"Pass","Fail"),"Check type"))))))))))
A14: S2-008 | B14: A | C14: Areas | D14: Hand unit U3: built-up area | E14: m² | F14: Book | G14: Unit drawn by hand with known areas | H14: Within 2% of correct answer | L14: =IF(X14="","",X14) | M14: =IF(O14<>"",O14,Y14) | R14: RERA Act 2016 Sec. 2(k) (carpet) | S14: n/a | T14: ±% | V14: 2 | W14: =IF(AND(ISNUMBER(I14),ISNUMBER(J14)),I14-J14,"") | X14: =IF(AND(ISNUMBER(I14),ISNUMBER(J14)),IF(J14=0,"",(I14-J14)/ABS(J14)),"") | Y14: =IF(T14="Advisory","No pass mark",IF(T14="Manual","Claude will check",IF(I14="","Not done yet",IF(T14="Exact",IF(AND(ISNUMBER(I14),ISNUMBER(J14)),IF(ROUND(I14,2)=ROUND(J14,2),"Pass","Fail"),IF(TRIM(LOWER(I14&""))=TRIM(LOWER(J14&"")),"Pass","Fail")),IF(T14="Min",IF(I14>=U14-1E-9,"Pass","Fail"),IF(T14="Between",IF(AND(I14>=U14,I14<=V14),"Pass","Fail"),IF(J14="","Not done yet",IF(T14="±%",IF(X14="","Check correct answer",IF(ABS(X14)*100<=V14+1E-9,"Pass","Fail")),IF(T14="% range",IF(X14="","Check correct answer",IF(AND(X14*100>=U14-1E-9,X14*100<=V14+1E-9),"Pass","Fail")),IF(T14="±abs",IF(ABS(W14)<=V14+1E-9,"Pass","Fail"),"Check type"))))))))))
